## 오류 검사


### 예외 발생

예외는 오류에 대한 신호로 사용된다. 예외를 일으키고 싶으면 raise 문을 사용한다

```python
if name not in authorized:
    raise RuntimeError(f'{name} not authorized')
```

### 예외 처리

```python
try:
    authenticate(username)
except RuntimeError as e:
    print(e)
```


예외는 처음 일치하는 except까지 전파된다.

```python
def grok():
    ...
    raise RuntimeError('Whoa!')   # 여기서 예외가 발생

def spam():
    grok()                        # 호출하면 예외가 발생

def bar():
    try:
       spam()
    except RuntimeError as e:     # 예외를 여기서 잡음
        ...

def foo():
    try:
         bar()
    except RuntimeError as e:     # 예외는 여기 도달하지 않음
        ...

foo()
```

예외를 처리하려면 except 블록에 문장을 넣는다. 예외를 처리하는 데 사용하고 싶은 문장을 무엇이든 넣을 수 있다.

```python
def grok(): ...
    raise RuntimeError('Whoa!')

def bar():
    try:
      grok()
    except RuntimeError as e:   # 예외를 여기서 잡음
        statements              # 이 문장을 사용
        문장
        ...

bar()
```

처리한 다음, try-except 이후 첫 번째 문장으로 실행을 재개한다.

```python
def grok(): ...
    raise RuntimeError('Whoa!')

def bar():
    try:
      grok()
    except RuntimeError as e:   # 예외를 여기서 잡음
        문장
        문장
        ...
    문장                                # 예외를 여기서 재개
    문장                                # 여기서 계속
    ...

bar()
```

### 예외를 다시 일으키기

붙잡은 오류를 전파하려면 raise를 사용한다.

```python
try:
    go_do_something()
except Exception as e:
    print('Computer says no. Reason :', e)
    raise
```

이렇게 하면 행동을 취하고(예: 로깅) 호출자에게 오류를 전달할 수 있다.

<br/>

### 예외 정의하기

사용자 정의 예외는 클래스에 의해 정의된다.

```python
class NetworkError(Exception):
    pass
```

예외는 항상 Exception으로부터 상속한다.

보통 그것들은 빈 클래스다. 몸체에 pass를 사용한다.

예외 계층을 직접 만들 수 있다.

```python
class AuthenticationError(NetworkError):
     pass

class ProtocolError(NetworkError):
    pass
```




<br/><br/><br/>
---
참조 : 
- [실용 파이썬 프로그래밍: 프로그래밍 유경험자를 위한 강의](https://wikidocs.net/84383)
 